Workbook

Sheet блок-схема
B2: Алгоритм расчета совокупной стоимости владения и оценки эффективности ИТ-проекта
A37: *- указан № таблицы как в Приложении
A39: **- чистый денежный поток (ЧДП)

Sheet А1.1.1
D1: Таблица А 1.1.1
A3: Справочник статей расходов (условно-прямых), связанных с разработкой ИТ-проекта
A5: Статья затрат | B5: Обозна- чение | C5: Метод расчета | D5: Примечание
A6: 1. Условно-прямые расходы, руб. | B6: РПр_Р | D6: Учитываются расходы, непосредственно относящиеся только к рассматриваемой системе
A7: 1.1. Расходы на оборудование, руб. | B7: РОб
A8: 1.1.1. Расходы на закупку оборудования, руб. | B8: РОб 1 | C8: Прямой счет фактических расходов (цена, доставка, монтаж, системное ПО) | D8: В случае закупки в период разработки системы
A9: 1.1.2. Сумма амортизации капитальных вложений в оборудование, руб. | B9: РОб 2 | C9: где ТП/И - срок полезного использования оборудования, месяцев (ТП/И устанавливается исходя из информации о том, сколько будет использоваться данный объект до его полной замены или модернизации. Если ТП/И меньше жизненного цикла системы, то на соответствующий год в расчете должны быть заложены расходы на закупку оборудования для замены или модернизации) | D9: В случае использования оборудования, ранее закупленного
A10: 1.1.3. Расходы на комплектующие, руб. | B10: РОб 3 | C10: Прямой счет фактических расходов или с помощью нормативного коэффициента к стоимости оборудования
A11: 1.1.4. Расходы на эксплуатацию оборудования, предназначенного для разработки системы, руб. | B11: РОб 4 | C11: где РРасх - стоимость расходных материалов, руб.; Кэи - Коэффициент использования электроустановок (принимается равным 0,9); WОб - суммарная установочная мощность оборудования, КВт.; Fоб - фонд времени работы оборудования, часы, ЦЭл - цена одного КВт-часа э/энергии, руб.
A12: 1.1.5. Стоимость обслуживания оборудования, предназначенного для разработки системы по договору, руб. | B12: РОб 5 | C12: Стоимость по договору обслуживания, руб. | D12: В случае наличия такого договора
A13: 1.1.6. Стоимость аренды оборудования предназначенного для разработки системы, руб. | B13: РОб 6 | C13: Стоимость по договору аренды, руб. | D13: В случае наличия такого договора
A14: 1.2. Расходы на программное обеспечение (ПО), руб. | B14: РПО
A15: 1.2.1. Расходы на закупку ПО, руб. | B15: РПО 1 | C15: Прямой счет фактических расходов (цена, доставка и т.д.) | D15: В случае закупки в период жизненного цикла
A16: 1.2.2. Сумма ежегодного списания затрат на ПО (аналог амортизации), руб. | B16: РПО 2 | C16: где ТП/И - срок полезного использования ПО, месяцев (ТП/И устанавливается исходя из информации о том, сколько будет использоваться данное программное обеспечение до его полной замены. Если ТП/И меньше жизненного цикла подсистемы (задачи), то на соответствующий год в расчете должны быть заложены расходы на закупку нового программного обеспечения для замены) | D16: В случае использования ПО, ранее закупленного
A17: 1.2.3. Затраты на аренду ПО, руб. | B17: РПО 3 | C17: Стоимость по договору аренды | D17: В случае наличия такого договора
A18: 1.2.4. Стоимость актуализации, поддержки и сопровождения ПО, руб. | B18: РПО 4 | C18: Стоимость стоимость по договорам обновления ПО, поддержки и сопровождения | D18: В случае наличия таких договоров
A19: 1.3. Административные расходы, руб. | B19: РАдм
A20: 1.3.1. Затраты на обучение разработчиков вопросам информационных технологий и систем, руб. | B20: РАдм 1 | C20: Стоимость услуг по договорам на обучение персонала | D20: В случае наличия таких договоров
A21: 1.3.2. Затраты на решение задач административного характера, порученные другим организациям в порядке аутсорсинга, руб. | B21: РАдм 2 | C21: Стоимость услуг по договорам аутсорсинга | D21: В случае наличия таких договоров
A22: 1.4. Расходы на оплату труда, связанные с разработкой системы руб. | B22: РФОТ
A23: 1.4.1. Расходы на оплату труда сотрудников по стадиям разработки системы (проектирование, разработка, тестирование, документирование), всего в т.ч.: | B23: РФОТ 1
A24: проектирование | B24: РФОТ 1_1 | C24: , где tр - месячная трудоемкость выполнения работ по разработке подсистемы(проектирование), часов ; Чр - среднечасовая ставка проектировщика (с учетом премий, компенсаций), руб.; R - коэффициент, учитывающий отчисления в социальные фонды | D24: Среднечасовая ставка = месячный оклад / 160 часов. Коэффициент R = 1,302.
A25: разработка | B25: РФОТ 1_2 | C25: расчет производится аналогично РФОТ1_1 | D25: в случае необходимости выполнения данной стадии на этапе разработки
A26: тестирование | B26: РФОТ 1_3 | C26: расчет производится аналогично РФОТ1_2
A27: документирование | B27: РФОТ 1_4 | C27: расчет производится аналогично РФОТ1_3
A28: 1.4.2. Расходы на оплату услуг сторонних разработчиков и консультантов по направлениям разработки системы, всего в т.ч.: | B28: РФОТ 2 | D28: В случае наличия таких договоров
A29: проектирование | B29: РФОТ 2_1 | C29: Стоимость по договорам аутсорсинга
A30: разработка | B30: РФОТ 2_2 | C30: Стоимость по договорам аутсорсинга
A31: тестирование | B31: РФОТ 2_3 | C31: Стоимость по договорам аутсорсинга
A32: документирование | B32: РФОТ 2_4 | C32: Стоимость по договорам аутсорсинга
A33: 1.5. Расходы на связь и коммуникации, руб. | B33: РКом
A34: 1.5.1. Расходы на оплату труда персонала поддержки корпоративной сети, выделенных линий и каналов для системы, руб. | B34: РКом 1 | C34: где tк - месячная трудоемкость выполнения работ по поддержке коммуникаций, часов; ЧК - среднечасовая ставка работника службы поддержки корпоративной сети, выделенных линий и каналов (с учетом премий, компенсаций), руб.; R - коэффициент, учитывающий отчисления в социальные фонды | D34: при наличии такого персонала. Среднечасовая ставка = месячный оклад / 160 часов. Коэффициент R = 1,302.
A35: 1.5.2. Расходы на аренду выделенных линий и каналов на этапе разработки системы, руб. | B35: РКом 2 | C35: Стоимость услуг по договорам аренды | D35: В случае наличия таких договоров
A36: 1.5.3. Расходы на удаленный доступ на этапе разработки системы, руб. | B36: РКом 3 | C36: Стоимость услуг по договорам обеспечения удаленного доступа | D36: В случае наличия таких договоров
A37: 1.5.4. Стоимость поддержки и развития корпоративных сетей передачи данных на этапе разработки системы, руб. | B37: РКом 4 | C37: Стоимость услуг по договорам поддержки корпоративных сетей передачи данных | D37: В случае наличия таких договоров

Sheet А1.2.1
D1: Таблица А 1.2.1
A3: Справочник статей расходов (условно-прямых), связанных с эксплуатацией ИТ-проекта
A5: Статья затрат | B5: Обозна- чение | C5: Метод расчета | D5: Примечание
A6: 1. Условно-прямые расходы, руб. | B6: РПр_Э | D6: Учитываются расходы, непосредственно относящиеся только к рассматриваемой системе
A7: 1.1. Расходы на оборудование, руб. | B7: РОб
A8: 1.1.1. Расходы на закупку оборудования, руб. | B8: РОб 1 | C8: Прямой счет фактических расходов (цена, доставка, монтаж, системное ПО) | D8: В случае закупки в период жизненного цикла
A9: 1.1.2. Сумма амортизации капитальных вложений в оборудование, руб. | B9: РОб 2 | C9: где ТП/И - срок полезного использования оборудования (ТП/И устанавливается исходя из информации о том, сколько будет использоваться данный объект до его полной замены или модернизации. Если ТП/И меньше жизненного цикла системы, то на соответствующий год в расчете должны быть заложены расходы на закупку оборудования для замены или модернизации) | D9: В случае использования оборудования, ранее закупленного
A10: 1.1.3. Расходы на комплектующие, руб. | B10: РОб 3 | C10: Прямой счет фактических расходов или с помощью нормативного коэффициента к стоимости оборудования
A11: 1.1.4. Расходы на эксплуатацию оборудования,связанного с эксплуатацией системы руб. | B11: РОб 4 | C11: где РРасх - стоимость расходных материалов, руб.; Кэи - Коэффициент использования электроустановок (принимается равным 0,9); WОб - суммарная установочная мощность оборудования, КВт.; Fоб - фонд времени работы оборудования, часы, ЦЭл - цена одного КВт-часа э/энергии, руб.
A12: 1.1.5. Стоимость обслуживания оборудования связанного с эксплуатацией системы по договору, руб. | B12: РОб 5 | C12: Стоимость по договору обслуживания | D12: В случае наличия такого договора
A13: 1.1.6. Стоимость аренды оборудования связанного с эксплуатацией системы, руб. | B13: РОб 6 | C13: Стоимость по договору аренды | D13: В случае наличия такого договора
A14: 1.2. Расходы на программное обеспечение (ПО), руб. | B14: РПО
A15: 1.2.1. Расходы на закупку ПО, руб. | B15: РПО 1 | C15: Прямой счет фактических расходов (цена, доставка, монтаж, системное ПО) | D15: В случае закупки в период жизненного цикла
A16: 1.2.2. Сумма ежегодного списания затрат на ПО (аналог амортизации), руб. | B16: РПО 2 | C16: где ТП/И - срок полезного использования ПО (ТП/И устанавливается исходя из информации о том, сколько будет использоваться данное программное обеспечение до его полной замены. Если ТП/И меньше жизненного цикла подсистемы (задачи), то на соответствующий год в расчете должны быть заложены расходы на закупку нового программного обеспечения для замены) | D16: В случае использования ПО, ранее закупленного
A17: 1.2.3. Затраты на аренду ПО, руб. | B17: РПО 3 | C17: Стоимость по договору аренды | D17: В случае наличия такого договора
A18: 1.2.4. Стоимость актуализации, поддержки и сопровождения ПО, руб. | B18: РПО 4 | C18: Стоимость по договорам обновления ПО, поддержки и сопровождения | D18: В случае наличия таких договоров
A19: 1.3. Административные расходы, руб. | B19: РАдм
A20: 1.3.1. Расходы на оплату труда пользователей (операторов) системы, руб. | B20: РАдм 1 | C20: , где tр - месячная трудоемкость выполнения работ, час ; Чр - среднечасовая ставка пользователя (оператора) системы (с учетом премий, компенсаций), руб.; R - коэффициент, учитывающий отчисления в социальные фонды | D20: Рассчитывается отдельно по всем работникам, имеющим разные ставки и роли. Среднечасовая ставка = месячный оклад / 160 часов. Коэффициент R = 1,302.
A21: 1.3.2. Расходы на консультационные услуги третьих фирм и аналогичные платежи, руб. | B21: РАдм 2 | C21: Стоимость работ и услуг по договорам на консультации, прочие услуги и работы, связанные с эксплуатацией подсистемы или задачи | D21: В случае наличия таких договоров
A22: 1.3.3. Расходы на решение задач, порученных другим организациям в порядке аутсорсинга, руб. | B22: РАдм 3 | C22: Стоимость услуг по договорам аутсорсинга | D22: В случае наличия таких договоров
A23: 1.3.4. Затраты на обучение персонала вопросам информационных технологий и систем, руб. | B23: РАдм 4 | C23: Стоимость услуг по договорам на обучение персонала | D23: В случае наличия таких договоров
A24: 1.4. Расходы на оплату труда, связанные с сопровождением и развитием системы, руб. | B24: РФОТ
A25: 1.4.1. Расходы на оплату труда сотрудников по сопровождению и развитию введенной в эксплуатацию системы по направлениям, руб. | B25: РФОТ 1
A26: сопровождение | B26: РФОТ 1_1 | C26: где tс - месячная трудоемкость выполнения работ по сопровождению подсистемы (задачи), час.; Чс - среднечасовая ставка работника службы сопровождения/развития (с учетом премий, компенсаций), руб.; К - коэффициент, учитывающий отчисления в социальные фонды | D26: Среднечасовая ставка = месячный оклад / 160 часов. Коэффициент R = 1,302.
A27: развитие | B27: РФОТ 1_2 | C27: расчет производится аналогично РФОТ1_1
A28: 1.4.2. Расходы на оплату услуг сторонних консультантов и сервисных организаций в части развития и сопровождения системы по направлениям, Всего в т.ч. | B28: РФОТ 2
A29: сопровождение | B29: РФОТ 2_1 | C29: Стоимость по договорам аутсорсинга | D29: В случае наличия таких договоров
A30: развитие | B30: РФОТ 2_2 | C30: Стоимость по договорам аутсорсинга | D30: В случае наличия таких договоров
A31: 1.5. Расходы на связь и коммуникации, руб. | B31: РКом
A32: 1.5.1. Расходы на оплату труда персонала поддержки корпоративной сети, выделенных линий и каналов для системы, руб. | B32: РКом 1 | C32: где tк - месячная трудоемкость выполнения работ по поддержке коммуникаций, часов; ЧК - среднечасовая ставка работника службы поддержки корпоративной сети, выделенных линий и каналов (с учетом премий, компенсаций), руб.; К - коэффициент, учитывающий оотчисления в социальные фонды | D32: при наличии такого персонала. Среднечасовая ставка = месячный оклад / 160 часов. Коэффициент R = 1,302.
A33: 1.5.2. Расходы на аренду выделенных линий и каналов для системы, руб. | B33: РКом 2 | C33: Стоимость услуг по договорам аренды | D33: В случае наличия таких договоров
A34: 1.5.3. Расходы на удаленный доступ для системы, руб. | B34: РКом 3 | C34: Стоимость услуг по договорам обеспечения удаленного доступа | D34: В случае наличия таких договоров
A35: 1.5.4. Стоимость поддержки и развития корпоративных сетей передачи данных для системы, руб. | B35: РКом 4 | C35: Стоимость услуг по договорам поддержки корпоративных сетей передачи данных | D35: В случае наличия таких договоров

Sheet А1.2.2
D1: Таблица А 1.2.2
A3: Справочник статей расходов (условно-косвенных), связанных с эксплуатацией ИТ-проекта
A5: Статья затрат | B5: Обозна- чение | C5: Метод расчета | D5: Примечание | E5: Поправки
A6: 2. Условно-косвенные расходы по подсистеме (системе), руб. | B6: РКос | D6: При упрощенном расчете рассчитываются только для этапа эксплуатации решения. Учитывается часть расходов на систему информационного менеджмента организации (общесистемных), относящаяся к рассматриваемой подсистеме (задаче)
A7: 2.1. Косвенные расходы на общесистемное оборудование, руб. | B7: РКОб | D7: Часть общих расходов за рассматриваемый год, относящихся к создаваемой системе
A8: 2.1.1. Расходы на закупку общесистемного оборудования в год, руб. | B8: РКОб 1 | C8: Прямой счет фактических расходов (цена, доставка, монтаж, системное ПО) | D8: В случае закупки в период жизненного цикла
A9: 2.1.2. Сумма амортизации капитальных вложений в общесистемное оборудование, руб. | B9: РКОб 2 | C9: где ТП/И - срок полезного использования оборудования (значение выбирается также как для аналогичной статьи условно-прямых расходов) | D9: В случае использования оборудования, ранее закупленного, или если срок полезного использования меньше длительности жизненного цикла системы
A10: 2.1.3. Расходы на общесистемные комплектующие за год, руб. | B10: РКОб 3 | C10: Прямой счет фактических расходов или с помощью нормативного коэффициента к стоимости оборудования
A11: 2.1.4. Расходы на эксплуатацию общесистемного оборудования, руб. | B11: РКОб 4 | C11: где РОРасх - годовая стоимость общесистемных расходных материалов, руб.; Кэи - Коэффициент использования электроустановок (принимается 0,9); Wооб - суммарная установочная мощность общесистемного оборудования, Fооб - годовой фонд времени работы оборудования , ЦЭл - цена одного КВт-часа э/энергии
A12: 2.1.5. Стоимость обслуживания общесистемного оборудования по договору, руб. | B12: РКОб 5 | C12: Стоимость по договору обслуживания | D12: В случае наличия такого договора
A13: 2.1.6. Ежегодная стоимость аренды общесистемного оборудования, руб. | B13: РКОб 6 | C13: Стоимость по договору аренды | D13: В случае наличия такого договора
A14: 2.1.7. Коэффициент участия общесистемного оборудования в системе | B14: РУОб | C14: Доля общесистемных ресурсов, связываемых с рассматриваемой подсистемой. Ррассчитывается следующими способами: 1) отношение прямых расходов на оборудование подсистемы к суммарной величине прямых расходов на оборудование всех подсистем 2) Соотношение объемов занимаемой дисковой памяти на общесистемных ресурсах 3) экспертным путем
A15: 2.2. Косвенные расходы на общесистемное программное обеспечение (ПО), руб. | B15: РКПО
A16: 2.2.1. Расходы на закупку общесистемного ПО за год, руб. | B16: РКПО 1 | C16: Прямой счет фактических расходов (цена, доставка, установка) | D16: В случае закупки в период жизненного цикла
A17: 2.2.2. Сумма ежегодного списания затрат на общесистемное ПО, руб. | B17: РКПО 2 | C17: где ТП/И - срок полезного использования ПО (значение выбирается также как для аналогичной статьи условно-прямых расходов) | D17: В случае использования ПО, ранее закупленного, или если его срок полезного использования меньше длительности жизненного цикла системы
A18: 2.2.3. Затраты на аренду общесистемного ПО, руб. | B18: РКПО 3 | C18: Стоимость по договору аренды | D18: В случае наличия такого договора
A19: 2.2.4. Стоимость актуализации, поддержки и сопровождения общесистемного ПО за год, руб. | B19: РКПО 4 | C19: Стоимость по договорам обновления ПО, поддержки и сопровождения | D19: В случае наличия таких договоров
A20: 2.2.5. Коэффициент участия общесистемного ПО в подсистеме | B20: РУПО | C20: Доля общесистемных ресурсов, связываемых рассматриваемой подсистемой. Рассчитывается как 1) Отношение прямых расходов на ПО подсистемы к суммарной величине прямых расходов на ПО всех подсистем 2) Соотношением объемов занимаемой дисковой памяти на общесистемных ресурсах 3) экспертным путем
A21: 2.3. Косвенные административные расходы, руб. | B21: РКАдм
A22: 2.3.1. Расходы на оплату труда лиц, работающих со всей системой (общесистемный персонал), за год, руб. | B22: РКАдм 1 | C22: где FКАдм - месячный фонд времени работы работников; ЧКАдм - среднечасовая ставка работника (с учетом премий, компенсаций); R- коэффициент, учитывающий отчисления в социальные фонды | D22: Рассчитывается отдельно по всем работникам, имеющим разные ставки и роли
A23: 2.3.2. Расходы на консультационные услуги третьих фирм и аналогичные платежи за год, относящиеся ко всей системе организации, руб. | B23: РКАдм 2 | C23: Стоимость работ и услуг по договорам на консультации, прочие услуги и работы, связанные с эксплуатацией системы | D23: В случае наличия таких договоров
A24: 2.3.3. Расходы на решение задач общесистемного характера, порученных другим организациям в порядке аутсорсинга, руб. | B24: РКАдм 3 | C24: Стоимость услуг по договорам аутсорсинга | D24: В случае наличия таких договоров
A25: 2.3.4. Ежегодные затраты на обучение персонала вопросам информационных технологий и систем информационного менеджмента в целом, руб. | B25: РКАдм 4 | C25: Стоимость услуг по договорам на обучение персонала | D25: В случае наличия таких договоров
A26: 2.3.5. Коэффициент участия общесистемного персонала в подсистеме | B26: РУАдм | C26: Доля общесистемных работ, связываемых с рассматриваемой подсистемой. Рассчитывается следующими методами: 1) Отношение прямых расходов на работы с подсистемой к суммарной величине прямых расходов на работы для всех подсистем. 2) экспертным путем.
A27: 2.4. Косвенные расходы на оплату труда, связанные с сопровождением и развитием системы, руб. | B27: РКФОТ
A28: 2.4.1. Расходы на оплату труда сотрудников по сопровождению и развитию общесистемных ресурсов информационного менеджмента в течение года, руб., Всего в т.ч.: | B28: РКФОТ 1
A29: сопровождение | B29: РКФОТ 1_1 | C29: , где tОс - месячная трудоемкость выполнения работ по сопровождению общесистемных ресурсов; Ккфот - коэффициент, характеризующий долю времени, которую работник тратит на работу с системой,ЧОс - среднечасовая ставка работника службы сопровождения (с учетом премий, компенсаций); R - коэффициент, учитывающий отчисления в социальные фонды | D29: Среднечасовая ставка = месячный оклад / 160 часов. Коэффициент R = 1,302.
A30: развитие | B30: РКФОТ 1_2 | C30: расчет производится аналогично РКФОТ1_1
A31: 2.4.2. Расходы на оплату услуг сторонних консультантов и сервисных организаций в части развития и сопровождения общесистемных ресурсов информационного менеджмента в течение года, Всего в т.ч. | B31: РКФОТ 2
A32: сопровождение | B32: РКФОТ 2_1 | C32: Стоимость по договорам аутсорсинга | D32: В случае наличия таких договоров
A33: развитие | B33: РКФОТ 2_2 | C33: Стоимость по договорам аутсорсинга | D33: В случае наличия таких договоров
A34: 2.4.5. Коэффициент участия общесистемных работ в разработке, развитии и сопровождении подсистемы | B34: КУФОТ | C34: Доля общесистемных работ, связываемых с рассматриваемой системой (рассчитывается как отношение прямых расходов на работы с системой к суммарной величине прямых расходов на работы для всех систем. Также может оцениваться экспертным путем)
A35: 2.5. Косвенные расходы на связь и коммуникации для рассматриваемой подсистемы (системы), руб. | B35: РККом
A36: 2.5.1. Расходы на оплату труда персонала поддержки общей корпоративной сети, выделенных линий и каналов за год, руб. | B36: РККом 1 | C36: где tк - месячная трудоемкость выполнения работ по поддержке коммуникаций, часов; Чк- среднечасовая ставка работника службы поддержки корпоративной сети, выделенных линий и каналов (с учетом премий, компенсаций), руб.; К - коэффициент, учитывающий оотчисления в социальные фонды | D36: при наличии такого персонала.Среднечасовая ставка = месячный оклад / 160 часов. Коэффициент R = 1,302.
A37: 2.5.2. Расходы на аренду выделенных общесистемных линий и каналов за год, руб. | B37: РККом 2 | C37: Стоимость услуг по договорам аренды | D37: В случае наличия таких договоров
A38: 2.5.3. Расходы на удаленный общесистемный доступ за год, руб. | B38: РККом 3 | C38: Стоимость услуг по договорам обеспечения удаленного доступа | D38: В случае наличия таких договоров
A39: 2.5.4. Стоимость поддержки и развития общесистемных корпоративных сетей передачи данных, руб. | B39: РККом 4 | C39: Стоимость услуг по договорам поддержки корпоративных сетей передачи данных | D39: В случае наличия таких договоров
A40: 2.5.5. Коэффициент участия общесистемных работ по коммуникациям в разработке, развитии и сопровождении подсистемы | B40: КУКом | C40: Доля общесистемных работ, связываемых с рассматриваемой подсистемой (рассчитывается как отношение прямых расходов на работы с подсистемой к суммарной величине прямых расходов на работы для всех подсистем. Также может оцениваться экспертным путем)

Sheet А1.2.3
D1: Таблица А 1.2.3
A3: Справочник статей расходов (непредвиденных), связанных с эксплуатацией ИТ-проекта
A5: Статья затрат | B5: Обозна- чение | C5: Метод расчета | D5: Примечание
A6: 3. Непредвиденные расходы, руб. | B6: РНепр | D6: При упрощенном расчете рассчитываются только для этапа эксплуатации решения
A7: 3.1. Расходы на операции конечных пользователей | B7: РПольз
A8: 3.1.1. Сумма оплаты труда, в соответствии с количеством часов, затраченных на самообучение сотрудников | B8: РПольз 1 | C8: где tП - суммарные месячные затраты времени сотрудников на самообучение, час.; ЧП- среднечасовая ставка работника (с учетом премий, компенсаций), руб.; R - коэффициент, учитывающий отчисления в социальные фонды | D8: Среднечасовая ставка = месячный оклад / 160 часов. Коэффициент R = 1,302.
A9: 3.1.2. Сумма оплаты труда, соответствующая количеству часов на обслуживание файлов, компьютера и программ | B9: РПольз 2 | C9: где tФ - суммарные месячные затраты времени сотрудников на обслуживание файлов и баз данных, час.; Чп - среднечасовая ставка работника (с учетом премий, компенсаций), руб.; R - коэффициент, учитывающий отчисления в социальные фонды | D9: Среднечасовая ставка = месячный оклад / 160 часов. Коэффициент R = 1,302.
A10: 3.2. Расходы на простои | B10: РПрос | D10: Общие расходы за месяц
A11: 3.2.1. Затраты по количеству часов простоя в соответствии с плановыми или внеплановыми остановками в работе | B11: РПрос 1 | C11: где FП - месячный фонд времени работы персонала, работающего с подсистемой (задачей); КПрос 1 - доля времени простоев= 0,0125; NП - численность персонала; Чп - среднечасовая ставка работника (с учетом премий, компенсаций); К- коэффициент отчислений в социальные фонды | D11: Коэффициент простоев КПрос 1 оценивается экспертным путем на основании имеющейся статистики
A12: 3.2.2. Затраты, соответствующие количеству часов потерь в работе пользователя по вине работника или нехватке возможностей системы | B12: РПрос 2 | C12: где FП - месячный фонд времени работы персонала, работающего с подсистемой (задачей);КПрос 2 - доля времени потерь=0,05; NП - численность персонала; Чп - среднечасовая ставка работника (с учетом премий, компенсаций); К - коэффициент отчислений в социальные фонды | D12: Коэффициент потерь КПрос 2 оценивается экспертным путем на основании имеющейся статистики

Sheet А1.3.1
D1: Таблица А 1.3.1
A3: Расчет совокупной стоимости владения для программного решения
A5: Статья затрат | B5: Обозна- чение | C5: Метод расчета | D5: Примечание
A6: ИТОГО | B6: ССВ | C6: ССВ=РПр_Р+РПр_Э+РКос+РНепр
A7: ТСО на одно рабочее место | B7: ссв | D7: Характеризует расходы на одно рабочее место подсистемы (задачи), что дает возможность оценки расходов при изменении масштаба системы

Sheet Б1.1.1
B1: Таблица Б 1.1.1
A2: Исходные данные для расчета затрат и показателей экономической эффективности
A3: Показатель | B3: Значение | D3: часть
A4: Количество автоматизируемых рабочих мест | B4: 5
A5: Срок службы ПК и ноутбуков, месяцев | B5: 36
A6: Стоимость ПК для разработки системы | B6: 75000
A7: Количество ПК для разработки системы | B7: 2
A8: Стоимость ранее закупленных ноутбуков, используемых на этапе разработки | B8: 75000
A9: Количество используемых ноутбуков на этапе разработки | B9: 0
A10: Стоимость аренды облачного сервера в месяц, руб. | B10: 0
A11: Замена программной системы и общесистемного оборудования по истечении срока службы, лет | B11: 5
A12: Фонд времени работы оборудования на этапе разработки системы в месяц, часов | B12: 160
A13: Стоимость расходных материалов (бумага, картриджи, канцтовары) в месяц, руб. | B13: 0
A14: Суммарная мощность электрооборудования, кВт | B14: 0.15
A15: Стоимость 1 кВт/ч электроэнергии, руб. | B15: 5.5
A16: Стоимость аренды ПО в месяц, руб | B16: =168699/12 -> 14058.25
A17: Стоимость ранее закупленного ПО, используемого для разработки | B17: 0
A18: Срок службы ПО, месяцев | B18: 12
A19: Фонд времени работы проектировщика на этапе разработки системы в месяц, часов | B19: 160
A20: Фонд времени работы разработчика на этапе разработки системы в месяц, часов | B20: 160
A21: Фонд времени работы тестировщика на этапе разработки системы в месяц, часов | B21: 160
A22: Фонд времени работы инженера по стандартизации на этапе разработки системы в месяц, часов | B22: 160
A23: Среднечасовая ставка лиц, работающих с системой на этапе ее разработки и проектирования, руб. | B23: =170000/160 -> 1062.5
A24: Стоимость ранее закупленных ПК, используемых на этапе эксплуатации системы (за единицу) | B24: 75000
A25: Количество ранее закупленных ПК, используемых на этапе эксплуатации системы | B25: 0
A26: Среднечасовая ставка лиц, работающих с системой на этапе эксплуатации в части сопровождения и развития , руб. | B26: =170000/160 -> 1062.5
A27: Фонд времени работы инженера по сопровождению на этапе эксплуатации системы в месяц, часов | B27: 20
A28: Фонд времени работы инженера по развитию на этапе эксплуатации системы в месяц, часов | B28: 2
A29: Затраты на повышение квалификации персонала в части ИТ | B29: 0
A30: Количество операторов, работающих с системой на этапе эксплуатации, чел. | B30: 1
A31: Среднечасовая ставка лиц, работающих с системой в период эксплуатации, руб. | B31: =120000/160 -> 750
A32: Среднечасовая ставка персонала поддержки общей корпоративной сети, выделенных линий и каналов , руб. | B32: 0
A33: Фонд времени работы оператора системы в месяц | B33: 2
A34: Среднечасовая ставка общесистемного персонала, руб. | B34: =120000/160 -> 750
A35: Расходы на закупку общесистемного оборудования | B35: 0
A36: Срок службы ранее закупленного общесистемного оборудования | B36: 30
A37: Стоимость ранее закупленного общесистемного оборудования | B37: 26000000
A38: Стоимость обслуживания общесистемного оборудования годовая | B38: 30000
A39: Расходы на закупку общесистемного ПО | B39: 0
A40: Стоимость доступа в Интернет за месяц, руб. | B40: 2400
...

Sheet В1.1.1
I1: Таблица В.1.1.1
A3: Расчет условно-прямых расходов, связанных с разработкой ИТ-проекта
A5: Статья затрат | C5: Всего | D5: в т.ч. по периодам (месяцам) разработки системы
D6: 1 месяц | E6: 2 месяц | F6: 3 месяц | G6: 4 месяц | H6: 5 месяц | I6: 6 месяц
A7: 1. Условно-прямые расходы, руб. | B7: РПр_Р | C7: =C8+C15+C20+C23+C34 -> 1425333.9 | D7: =D8+D15+D20+D23+D34 -> 475111.3 | E7: =E8+E15+E20+E23+E34 -> 364441.3 | F7: =F8+F15+F20+F23+F34 -> 585781.3 | G7: =G8+G15+G20+G23+G34 -> 0 | H7: =H8+H15+H20+H23+H34 -> 0 | I7: =I8+I15+I20+I23+I34 -> 0
A8: 1.1. Расходы на оборудование, руб. | B8: РОб | C8: =SUM(C9:C14) -> 356.4 | D8: =SUM(D9:D14) -> 118.8 | E8: =SUM(E9:E14) -> 118.8 | F8: =SUM(F9:F14) -> 118.8 | G8: =SUM(G9:G14) -> 0 | H8: =SUM(H9:H14) -> 0 | I8: =SUM(I9:I14) -> 0
A9: 1.1.1. Расходы на закупку оборудования, руб. | B9: РОб 1 | C9: =SUM(D9:I9) -> 0 | D9: ='Б1.1.1'!$B$8/'Б1.1.1'!$B$5*'Б1.1.1'!$D$13 -> 0 | E9: ='Б1.1.1'!$B$8/'Б1.1.1'!$B$5*'Б1.1.1'!$D$13 -> 0 | F9: ='Б1.1.1'!$B$8/'Б1.1.1'!$B$5*'Б1.1.1'!$D$13 -> 0
A10: 1.1.2. Сумма амортизации капитальных вложений в оборудование, руб. | B10: РОб 2 | C10: =SUM(D10:I10) -> 0 | D10: =('Б1.1.1'!$B$8+'Б1.1.1'!$B$24)/'Б1.1.1'!$B$5*'Б1.1.1'!$B$9 -> 0 | E10: =D10 -> 0 | F10: =E10 -> 0
A11: 1.1.3. Расходы на комплектующие, руб | B11: РОб 3 | C11: =SUM(D11:I11) -> 0 | D11: 0 | E11: 0 | F11: 0
A12: 1.1.4. Расходы на эксплуатацию оборудования, предназначенного для разработки системы, руб. | B12: РОб 4 | C12: =SUM(D12:I12) -> 356.4 | D12: ='Б1.1.1'!$B$13+(0.9*'Б1.1.1'!$B$14*'Б1.1.1'!$B$12*'Б1.1.1'!$B$15) -> 118.8 | E12: ='Б1.1.1'!$B$13+(0.9*'Б1.1.1'!$B$14*'Б1.1.1'!$B$12*'Б1.1.1'!$B$15) -> 118.8 | F12: ='Б1.1.1'!$B$13+(0.9*'Б1.1.1'!$B$14*'Б1.1.1'!$B$12*'Б1.1.1'!$B$15) -> 118.8
A13: 1.1.5. Стоимость обслуживания оборудования, предназначенного для разработки системы по договору, руб. | B13: РОб 5 | C13: =SUM(D13:I13) -> 0 | D13: 0 | E13: 0 | F13: 0
A14: 1.1.6. Стоимость аренды оборудования предназначенного для разработки системы, руб. | B14: РОб 6 | C14: =SUM(D14:I14) -> 0 | D14: ='Б1.1.1'!$B$10 -> 0 | E14: ='Б1.1.1'!$B$10 -> 0 | F14: ='Б1.1.1'!$B$10 -> 0
A15: 1.2. Расходы на программное обеспечение (ПО), руб. | B15: РПО | C15: =SUM(C16:C19) -> 421747.5 | D15: =SUM(D16:D19) -> 140582.5 | E15: =SUM(E16:E19) -> 140582.5 | F15: =SUM(F16:F19) -> 140582.5 | G15: =SUM(G16:G19) -> 0 | H15: =SUM(H16:H19) -> 0 | I15: =SUM(I16:I19) -> 0
A16: 1.2.1. Расходы на закупку ПО, руб. | B16: РПО 1 | C16: =SUM(D16:I16) -> 421747.5 | D16: =('Б1.1.1'!$B$39*'Б1.1.1'!$B$4)+('Б1.1.1'!$B$47*'Б1.1.1'!$B$4)+('Б1.1.1'!$B$16*'Б1.1.1'!$B$4)+('Б1.1.1'!$B$17*'Б1.1.1'!$B$4) -> 140582.5 | E16: =('Б1.1.1'!B39*'Б1.1.1'!B4)+('Б1.1.1'!B47*'Б1.1.1'!B4)+('Б1.1.1'!B16*'Б1.1.1'!B4)+('Б1.1.1'!B17*'Б1.1.1'!B4) -> 140582.5 | F16: =('Б1.1.1'!B39*'Б1.1.1'!B4)+('Б1.1.1'!B47*'Б1.1.1'!B4)+('Б1.1.1'!B16*'Б1.1.1'!B4)+('Б1.1.1'!B17*'Б1.1.1'!B4) -> 140582.5
A17: 1.2.2. Сумма ежегодного списания затрат на ПО (аналог амортизации), руб. | B17: РПО 2 | C17: =SUM(D17:I17) -> 0 | D17: ='Б1.1.1'!$B$17/'Б1.1.1'!$B$18 -> 0 | E17: ='Б1.1.1'!$B$17/'Б1.1.1'!$B$18 -> 0 | F17: ='Б1.1.1'!$B$17/'Б1.1.1'!$B$18 -> 0 | K17: Срок полезного использования ПО 10 лет, если другое не установлено в договором
A18: 1.2.3. Затраты на аренду ПО, руб. | B18: РПО 3 | C18: =SUM(D18:I18) -> 0 | D18: 0 | E18: 0 | F18: 0
A19: 1.2.4. Стоимость актуализации, поддержки и сопровождения ПО, руб. | B19: РПО 4 | C19: =SUM(D19:I19) -> 0 | D19: 0 | E19: 0 | F19: 0
A20: 1.3. Административные расходы, руб. | B20: РАдм | C20: =SUM(C21:C22) -> 0 | D20: =SUM(D21:D22) -> 0 | E20: =SUM(E21:E22) -> 0 | F20: =SUM(F21:F22) -> 0 | G20: =SUM(G21:G22) -> 0 | H20: =SUM(H21:H22) -> 0 | I20: =SUM(I21:I22) -> 0
A21: 1.3.1. Затраты на обучение разработчиков вопросам информационных технологий и систем, руб. | B21: РАдм 1 | C21: =SUM(D21:I21) -> 0 | D21: 0 | E21: 0 | F21: 0 | G21: 0 | H21: 0 | I21: 0
A22: 1.3.2. Затраты на решение задач административного характера, порученные другим организациям в порядке аутсорсинга, руб. | B22: РАдм 2 | C22: =SUM(D22:I22) -> 0 | D22: 0 | E22: 0 | F22: 0 | G22: 0 | H22: 0 | I22: 0
A23: 1.4. Расходы на оплату труда, связанные с разработке системы руб. | B23: РФОТ | C23: =C24+C29 -> 996030 | D23: =D24+D29 -> 332010 | E23: =E24+E29 -> 221340 | F23: =F24+F29 -> 442680 | G23: =G24+G29 -> 0 | H23: =H24+H29 -> 0 | I23: =I24+I29 -> 0
A24: 1.4.1. Расходы на оплату труда сотрудников по стадиям разработки системы (проектирование, разработка, тестирование, документирование), всего в т.ч.: | B24: РФОТ 1 | C24: =SUM(C25:C28) -> 996030 | D24: =D25+D26+D27+D28 -> 332010 | E24: =E25+E26+E27+E28 -> 221340 | F24: =F25+F26+F27+F28 -> 442680 | G24: =G25+G26+G27+G28 -> 0 | H24: =H25+H26+H27+H28 -> 0 | I24: =I25+I26+I27+I28 -> 0
A25: проектирование | B25: РФОТ 1_1 | C25: =SUM(D25:I25) -> 221340 | D25: ='Б1.1.1'!B23*'Б1.1.1'!B19*'Б1.1.1'!B41 -> 221340 | E25: 0 | F25: 0
A26: разработка | B26: РФОТ 1_2 | C26: =SUM(D26:I26) -> 332010 | D26: ='Б1.1.1'!B23*'Б1.1.1'!B20*'Б1.1.1'!B41/2 -> 110670 | E26: ='Б1.1.1'!B23*'Б1.1.1'!B20*'Б1.1.1'!B41 -> 221340 | F26: 0
A27: тестирование | B27: РФОТ 1_3 | C27: =SUM(D27:I27) -> 221340 | D27: 0 | E27: 0 | F27: ='Б1.1.1'!B23*'Б1.1.1'!B21*'Б1.1.1'!B41 -> 221340
A28: документирование | B28: РФОТ 1_4 | C28: =SUM(D28:I28) -> 221340 | D28: 0 | E28: 0 | F28: ='Б1.1.1'!B23*'Б1.1.1'!B22*'Б1.1.1'!B41 -> 221340
A29: 1.4.2. Расходы на оплату услуг сторонних разработчиков и консультантов по направлениям разработки системы, всего в т.ч.: | B29: РФОТ 2 | C29: =SUM(C30:C33) -> 0 | D29: =D30+D31+D32+D33 -> 0 | E29: =E30+E31+E32+E33 -> 0 | F29: =F30+F31+F32+F33 -> 0 | G29: =G30+G31+G32+G33 -> 0 | H29: =H30+H31+H32+H33 -> 0 | I29: =I30+I31+I32+I33 -> 0
A30: проектирование | B30: РФОТ 2_1 | C30: =SUM(D30:H31) -> 0 | D30: 0 | E30: 0 | F30: 0 | G30: 0 | H30: 0 | I30: 0
A31: разработка | B31: РФОТ 2_2 | C31: =SUM(D31:H32) -> 0 | D31: 0 | E31: 0 | F31: 0 | G31: 0 | H31: 0 | I31: 0
A32: тестирование | B32: РФОТ 2_3 | C32: =SUM(D32:H33) -> 0 | D32: 0 | E32: 0 | F32: 0 | G32: 0 | H32: 0 | I32: 0
A33: документирование | B33: РФОТ 2_4 | C33: =SUM(D33:H33) -> 0 | D33: 0 | E33: 0 | F33: 0 | G33: 0 | H33: 0 | I33: 0
A34: 1.5. Расходы на связь и коммуникации, руб. | B34: РКом | C34: =SUM(C35:C38) -> 7200 | D34: =SUM(D35:D38) -> 2400 | E34: =SUM(E35:E38) -> 2400 | F34: =SUM(F35:F38) -> 2400 | G34: =SUM(G35:G38) -> 0 | H34: =SUM(H35:H38) -> 0 | I34: =SUM(I35:I38) -> 0
A35: 1.5.1. Расходы на оплату труда персонала поддержки корпоративной сети, выделенных линий и каналов для системы, руб. | B35: РКом 1 | C35: =SUM(D35:I35) -> 0 | D35: 0 | E35: 0 | F35: 0
A36: 1.5.2. Расходы на аренду выделенных линий и каналов на этапе разработки системы, руб. | B36: РКом 2 | C36: =SUM(D36:I36) -> 0 | D36: 0 | E36: 0 | F36: 0
A37: 1.5.3. Расходы на удаленный доступ на этапе разработки системы, руб. | B37: РКом 3 | C37: =SUM(D37:I37) -> 7200 | D37: ='Б1.1.1'!$B$40 -> 2400 | E37: ='Б1.1.1'!$B$40 -> 2400 | F37: ='Б1.1.1'!$B$40 -> 2400
A38: 1.5.4. Стоимость поддержки и развития корпоративных сетей передачи данных на этапе разработки системы, руб. | B38: РКом 4 | C38: =SUM(D38:I38) -> 0 | D38: 0 | E38: 0 | F38: 0

Sheet В1.2.1
S1: Таблица В 1.2.1
A3: Расчет расходов (условно-прямых), связанных с эксплуатацией ИТ-проекта
A5: Статья затрат | B5: Обозна- чение | C5: Всего | D5: в т.ч. по периодам эксплуатации системы
D6: 1 год, всего | E6: в т.ч. по периодам (месяцам) 1-го года жизни решения | Q6: 2 | R6: 3 | S6: 4 | T6: 5
E7: 1 месяц (разработка) | F7: 2 месяц (разработка) | G7: 3 месяц (разработка) | H7: 4 месяц | I7: 5 месяц | J7: 6 месяц | K7: 7 месяц | L7: 8 месяц | M7: 9 месяц | N7: 10 месяц | O7: 11 месяц | P7: 12 месяц | R7: 3
A8: 1. Условно-прямые расходы, руб. | B8: РПр_Э | C8: =C9+C16+C21+C33+C26 -> 1046570.9 | D8: =D9+D16+D21+D33+D26 -> 285428.44 | E8: =E9+E16+E21+E33+E26 -> 0 | F8: =F9+F16+F21+F33+F26 -> 0 | G8: =G9+G16+G21+G33+G26 -> 0 | H8: =H9+H16+H21+H33+H26 -> 30792.021 | I8: =I9+I16+I21+I33+I26 -> 30792.021 | J8: =J9+J16+J21+J33+J26 -> 33558.771 | ... T8: =T9+T16+T21+T33+T26 -> 0
A9: 1.1. Расходы на оборудование, руб. | B9: РОб | C9: =SUM(C10:C15) -> 0 | D9: =SUM(D10:D15) -> 0 | E9: =SUM(E10:E15) -> 0 | F9: =SUM(F10:F15) -> 0 | G9: =SUM(G10:G15) -> 0 | H9: =SUM(H10:H15) -> 0 | I9: =SUM(I10:I15) -> 0 | J9: =SUM(J10:J15) -> 0 | ... T9: =SUM(T10:T15) -> 0
A10: 1.1.1. Расходы на закупку оборудования, руб. | B10: РОб 1 | C10: =D10+Q10+R10+S10+T10 -> 0 | D10: =SUM(E10:P10) -> 0 | H10: 0 | I10: 0 | J10: 0 | K10: 0 | L10: 0 | M10: 0 | N10: 0 | O10: 0 | P10: 0 | Q10: 0 | R10: 0
A11: 1.1.2. Сумма амортизации капитальных вложений в оборудование, руб. | B11: РОб 2 | C11: =D11+Q11+R11+S11+T11 -> 0 | D11: =SUM(E11:P11) -> 0 | E11: 0 | F11: 0 | G11: 0 | H11: =('Б1.1.1'!$B$24*'Б1.1.1'!$B$25)/'Б1.1.1'!$B$5 -> 0 | I11: =('Б1.1.1'!$B$24*'Б1.1.1'!$B$25)/'Б1.1.1'!$B$5 -> 0 | J11: =('Б1.1.1'!$B$24*'Б1.1.1'!$B$25)/'Б1.1.1'!$B$5 -> 0 | K11: =('Б1.1.1'!$B$24*'Б1.1.1'!$B$25)/'Б1.1.1'!$B$5 -> 0 | L11: =('Б1.1.1'!$B$24*'Б1.1.1'!$B$25)/'Б1.1.1'!$B$5 -> 0 | M11: =('Б1.1.1'!$B$24*'Б1.1.1'!$B$25)/'Б1.1.1'!$B$5 -> 0 | N11: =('Б1.1.1'!$B$24*'Б1.1.1'!$B$25)/'Б1.1.1'!$B$5 -> 0 | O11: =('Б1.1.1'!$B$24*'Б1.1.1'!$B$25)/'Б1.1.1'!$B$5 -> 0 | P11: =('Б1.1.1'!$B$24*'Б1.1.1'!$B$25)/'Б1.1.1'!$B$5 -> 0 | Q11: =P11*12 -> 0 | R11: =P11*12 -> 0
A12: 1.1.3. Расходы на комплектующие, руб | B12: РОб 3 | C12: =D12+Q12+R12+S12+T12 -> 0 | D12: =SUM(E12:P12) -> 0 | H12: 0 | I12: 0 | J12: 0 | K12: 0 | L12: 0 | M12: 0 | N12: 0 | O12: 0 | P12: 0 | Q12: 0 | R12: 0
A13: 1.1.4. Расходы на эксплуатацию оборудования, руб. | B13: РОб 4 | C13: =D13+Q13+R13+S13+T13 -> 0 | D13: =SUM(E13:P13) -> 0 | H13: 0 | I13: 0 | J13: 0 | K13: 0 | L13: 0 | M13: 0 | N13: 0 | O13: 0 | P13: 0 | Q13: 0 | R13: 0
A14: 1.1.5. Стоимость обслуживания оборудования по договору, руб. | B14: РОб 5 | C14: =D14+Q14+R14+S14+T14 -> 0 | D14: =SUM(E14:P14) -> 0 | H14: 0 | I14: 0 | J14: 0 | K14: 0 | L14: 0 | M14: 0 | N14: 0 | O14: 0 | P14: 0 | Q14: 0 | R14: 0
A15: 1.1.6. Стоимость аренды оборудования, руб. | B15: РОб 6 | C15: =D15+Q15+R15+S15+T15 -> 0 | D15: =SUM(E15:P15) -> 0 | H15: 0 | I15: 0 | J15: 0 | K15: 0 | L15: 0 | M15: 0 | N15: 0 | O15: 0 | P15: 0 | Q15: 0 | R15: 0
A16: 1.2. Расходы на программное обеспечение (ПО), руб. | B16: РПО | C16: =D16+Q16+R16+S16+T16 -> 38660.188 | D16: =SUM(D17:D20) -> 10543.688 | E16: =SUM(E17:E20) -> 0 | F16: =SUM(F17:F20) -> 0 | G16: =SUM(G17:G20) -> 0 | H16: =SUM(H17:H20) -> 1171.5208 | I16: =SUM(I17:I20) -> 1171.5208 | J16: =SUM(J17:J20) -> 1171.5208 | K16: =SUM(K17:K20) -> 1171.5208 | ... T16: =SUM(T17:T20) -> 0
A17: 1.2.1. Расходы на закупку ПО, руб. | B17: РПО 1 | C17: =D17+Q17+R17+S17+T17 -> 0 | D17: =SUM(E17:P17) -> 0
A18: 1.2.2. Сумма ежегодного списания затрат на ПО (аналог амортизации), руб. | B18: РПО 2 | C18: =D18+Q18+R18+S18+T18 -> 38660.188 | D18: =SUM(E18:P18) -> 10543.688 | E18: 0 | F18: 0 | G18: 0 | H18: ='Б1.1.1'!$B$47/'Б1.1.1'!$B$18 -> 1171.5208 | I18: ='Б1.1.1'!$B$47/'Б1.1.1'!$B$18 -> 1171.5208 | J18: ='Б1.1.1'!$B$47/'Б1.1.1'!$B$18 -> 1171.5208 | K18: ='Б1.1.1'!$B$47/'Б1.1.1'!$B$18 -> 1171.5208 | L18: ='Б1.1.1'!$B$47/'Б1.1.1'!$B$18 -> 1171.5208 | M18: ='Б1.1.1'!$B$47/'Б1.1.1'!$B$18 -> 1171.5208 | N18: ='Б1.1.1'!$B$47/'Б1.1.1'!$B$18 -> 1171.5208 | O18: ='Б1.1.1'!$B$47/'Б1.1.1'!$B$18 -> 1171.5208 | P18: ='Б1.1.1'!$B$47/'Б1.1.1'!$B$18 -> 1171.5208 | Q18: =P18*12 -> 14058.25 | R18: =P18*12 -> 14058.25
A19: 1.2.3. Затраты на аренду ПО, руб. | B19: РПО 3 | C19: =D19+Q19+R19+S19+T19 -> 0 | D19: =SUM(E19:P19) -> 0
A20: 1.2.4. Стоимость актуализации, поддержки и сопровождения ПО, руб. | B20: РПО 4 | C20: =D20+Q20+R20+S20+T20 -> 0 | D20: =SUM(E20:P20) -> 0
A21: 1.3. Административные расходы, руб. | B21: РАдм | C21: =SUM(C22:C25) -> 64449 | D21: =SUM(D22:D25) -> 17577 | E21: =SUM(E22:E25) -> 0 | F21: =SUM(F22:F25) -> 0 | G21: =SUM(G22:G25) -> 0 | H21: =SUM(H22:H25) -> 1953 | I21: =SUM(I22:I25) -> 1953 | J21: =SUM(J22:J25) -> 1953 | ... T21: =SUM(T22:T25) -> 0
A22: 1.3.1. Расходы на оплату труда пользователей (операторов) системы, руб. | B22: РАдм 1 | C22: =D22+Q22+R22+S22+T22 -> 64449 | D22: =SUM(E22:P22) -> 17577 | H22: ='Б1.1.1'!$B$33*'Б1.1.1'!$B$31*'Б1.1.1'!$B$30*'Б1.1.1'!$B$41 -> 1953 | I22: ='Б1.1.1'!$B$33*'Б1.1.1'!$B$31*'Б1.1.1'!$B$30*'Б1.1.1'!$B$41 -> 1953 | J22: ='Б1.1.1'!$B$33*'Б1.1.1'!$B$31*'Б1.1.1'!$B$30*'Б1.1.1'!$B$41 -> 1953 | K22: ='Б1.1.1'!$B$33*'Б1.1.1'!$B$31*'Б1.1.1'!$B$30*'Б1.1.1'!$B$41 -> 1953 | L22: ='Б1.1.1'!$B$33*'Б1.1.1'!$B$31*'Б1.1.1'!$B$30*'Б1.1.1'!$B$41 -> 1953 | M22: ='Б1.1.1'!$B$33*'Б1.1.1'!$B$31*'Б1.1.1'!$B$30*'Б1.1.1'!$B$41 -> 1953 | N22: ='Б1.1.1'!$B$33*'Б1.1.1'!$B$31*'Б1.1.1'!$B$30*'Б1.1.1'!$B$41 -> 1953 | O22: ='Б1.1.1'!$B$33*'Б1.1.1'!$B$31*'Б1.1.1'!$B$30*'Б1.1.1'!$B$41 -> 1953 | P22: ='Б1.1.1'!$B$33*'Б1.1.1'!$B$31*'Б1.1.1'!$B$30*'Б1.1.1'!$B$41 -> 1953 | Q22: =P22*12 -> 23436 | R22: =P22*12 -> 23436 | U22: второй и последующие годы =ФОТ месяц*12
A23: 1.3.2. Расходы на консультационные услуги третьих фирм и аналогичные платежи, руб. | B23: РАдм 2 | C23: =D23+Q23+R23+S23+T23 -> 0 | D23: =SUM(E23:P23) -> 0
A24: 1.3.3. Расходы на решение задач, порученных другим организациям в порядке аутсорсинга, руб. | B24: РАдм 3 | C24: =D24+Q24+R24+S24+T24 -> 0 | D24: =SUM(E24:P24) -> 0
A25: 1.3.4. Затраты на обучение персонала вопросам информационных технологий и систем, руб. | B25: РАдм 4 | C25: =D25+Q25+R25+S25+T25 -> 0 | D25: =SUM(E25:P25) -> 0
A26: 1.4. Расходы связанные с сопровождением и развитием системы, руб. | B26: РФОТ | C26: =C27+C30 -> 943461.75 | D26: =D27+D30 -> 257307.75 | E26: =E27+E30 -> 0 | F26: =F27+F30 -> 0 | G26: =G27+G30 -> 0 | H26: =H27+H30 -> 27667.5 | I26: =I27+I30 -> 27667.5 | J26: =J27+J30 -> 30434.25 | ... T26: =T27+T30 -> 0
A27: 1.4.1. Расходы на оплату труда сотрудников по сопровождению и развитию введенной в эксплуатацию системы по направлениям, руб. Всего, в т.ч. | B27: РФОТ 1 | C27: =C28+C29 -> 943461.75 | D27: =D28+D29 -> 257307.75 | E27: =E28+E29 -> 0 | F27: =F28+F29 -> 0 | G27: =G28+G29 -> 0 | H27: =H28+H29 -> 27667.5 | I27: =I28+I29 -> 27667.5 | J27: =J28+J29 -> 30434.25 | ... T27: =T28+T29 -> 0
A28: сопровождение | B28: РФОТ 1_1 | C28: =D28+Q28+R28+S28+T28 -> 913027.5 | D28: =SUM(E28:P28) -> 249007.5 | H28: ='Б1.1.1'!$B$26*'Б1.1.1'!$B$27*'Б1.1.1'!$B$48*'Б1.1.1'!$B$41 -> 27667.5 | I28: ='Б1.1.1'!$B$26*'Б1.1.1'!$B$27*'Б1.1.1'!$B$48*'Б1.1.1'!$B$41 -> 27667.5 | J28: ='Б1.1.1'!$B$26*'Б1.1.1'!$B$27*'Б1.1.1'!$B$48*'Б1.1.1'!$B$41 -> 27667.5 | K28: ='Б1.1.1'!$B$26*'Б1.1.1'!$B$27*'Б1.1.1'!$B$48*'Б1.1.1'!$B$41 -> 27667.5 | L28: ='Б1.1.1'!$B$26*'Б1.1.1'!$B$27*'Б1.1.1'!$B$48*'Б1.1.1'!$B$41 -> 27667.5 | M28: ='Б1.1.1'!$B$26*'Б1.1.1'!$B$27*'Б1.1.1'!$B$48*'Б1.1.1'!$B$41 -> 27667.5 | N28: ='Б1.1.1'!$B$26*'Б1.1.1'!$B$27*'Б1.1.1'!$B$48*'Б1.1.1'!$B$41 -> 27667.5 | O28: ='Б1.1.1'!$B$26*'Б1.1.1'!$B$27*'Б1.1.1'!$B$48*'Б1.1.1'!$B$41 -> 27667.5 | P28: ='Б1.1.1'!$B$26*'Б1.1.1'!$B$27*'Б1.1.1'!$B$48*'Б1.1.1'!$B$41 -> 27667.5 | Q28: =P28*12 -> 332010 | R28: =P28*12 -> 332010 | U28: второй и последующие годы =ФОТ месяц*12
A29: развитие | B29: РФОТ 1_2 | C29: =D29+Q29+R29+S29+T29 -> 30434.25 | D29: =SUM(E29:P29) -> 8300.25 | J29: ='Б1.1.1'!$B$28*'Б1.1.1'!$B$26*'Б1.1.1'!$B$49*'Б1.1.1'!$B$41 -> 2766.75 | M29: ='Б1.1.1'!$B$28*'Б1.1.1'!$B$26*'Б1.1.1'!$B$49*'Б1.1.1'!$B$41 -> 2766.75 | P29: ='Б1.1.1'!$B$28*'Б1.1.1'!$B$26*'Б1.1.1'!$B$49*'Б1.1.1'!$B$41 -> 2766.75 | Q29: =P29*4 -> 11067 | R29: =P29*4 -> 11067 | U29: четыре месяца в год
A30: 1.4.4. Расходы на оплату услуг консультантов и сервисных организаций в части развития и сопровождения системы по направлениям, руб. Всего, в т.ч. | B30: РФОТ 2 | C30: =C31+C32 -> 0 | D30: =D31+D32 -> 0 | E30: =E31+E32 -> 0 | F30: =F31+F32 -> 0 | G30: =G31+G32 -> 0 | H30: =H31+H32 -> 0 | I30: =I31+I32 -> 0 | J30: =J31+J32 -> 0 | ... T30: =T31+T32 -> 0
A31: сопровождение | B31: РФОТ 2_1 | C31: =D31+Q31+R31+S31+T31 -> 0 | D31: =SUM(E31:P31) -> 0
A32: развитие | B32: РФОТ 2_2 | C32: =D32+Q32+R32+S32+T32 -> 0 | D32: =SUM(E32:P32) -> 0
A33: 1.5. Расходы на связь и коммуникации, руб. | B33: РКом | C33: =SUM(C34:C37) -> 0 | D33: =SUM(D34:D37) -> 0 | E33: =SUM(E34:E37) -> 0 | F33: =SUM(F34:F37) -> 0 | G33: =SUM(G34:G37) -> 0 | H33: =SUM(H34:H37) -> 0 | I33: =SUM(I34:I37) -> 0 | J33: =SUM(J34:J37) -> 0 | ... T33: =SUM(T34:T37) -> 0
A34: 1.5.1. Расходы на оплату труда персонала поддержки корпоративной сети, выделенных линий и каналов для системы, руб. | B34: РКом 1 | C34: =D34+Q34+R34+S34+T34 -> 0 | D34: =SUM(E34:P34) -> 0 | H34: ='Б1.1.1'!B$32*'Б1.1.1'!B$51*'Б1.1.1'!B$50*'Б1.1.1'!B$41 -> 0 | I34: ='Б1.1.1'!$B$32*'Б1.1.1'!$B$51*'Б1.1.1'!$B$50*'Б1.1.1'!$B$41 -> 0 | J34: ='Б1.1.1'!$B$32*'Б1.1.1'!$B$51*'Б1.1.1'!$B$50*'Б1.1.1'!$B$41 -> 0 | K34: ='Б1.1.1'!$B$32*'Б1.1.1'!$B$51*'Б1.1.1'!$B$50*'Б1.1.1'!$B$41 -> 0 | L34: ='Б1.1.1'!$B$32*'Б1.1.1'!$B$51*'Б1.1.1'!$B$50*'Б1.1.1'!$B$41 -> 0 | M34: ='Б1.1.1'!$B$32*'Б1.1.1'!$B$51*'Б1.1.1'!$B$50*'Б1.1.1'!$B$41 -> 0 | N34: ='Б1.1.1'!$B$32*'Б1.1.1'!$B$51*'Б1.1.1'!$B$50*'Б1.1.1'!$B$41 -> 0 | O34: ='Б1.1.1'!$B$32*'Б1.1.1'!$B$51*'Б1.1.1'!$B$50*'Б1.1.1'!$B$41 -> 0 | P34: ='Б1.1.1'!$B$32*'Б1.1.1'!$B$51*'Б1.1.1'!$B$50*'Б1.1.1'!$B$41 -> 0 | Q34: =P34*12 -> 0 | R34: =P34*12 -> 0
A35: 1.5.2. Расходы на аренду выделенных линий и каналов для системы, руб. | B35: РКом 2 | C35: =D35+Q35+R35+S35+T35 -> 0 | D35: =SUM(E35:P35) -> 0 | H35: ='Б1.1.1'!$B$32*'Б1.1.1'!$B$51*'Б1.1.1'!$B$50*'Б1.1.1'!$B$41 -> 0 | I35: ='Б1.1.1'!$B$32*'Б1.1.1'!$B$51*'Б1.1.1'!$B$50*'Б1.1.1'!$B$41 -> 0 | J35: ='Б1.1.1'!$B$32*'Б1.1.1'!$B$51*'Б1.1.1'!$B$50*'Б1.1.1'!$B$41 -> 0 | K35: ='Б1.1.1'!$B$32*'Б1.1.1'!$B$51*'Б1.1.1'!$B$50*'Б1.1.1'!$B$41 -> 0 | L35: ='Б1.1.1'!$B$32*'Б1.1.1'!$B$51*'Б1.1.1'!$B$50*'Б1.1.1'!$B$41 -> 0 | M35: ='Б1.1.1'!$B$32*'Б1.1.1'!$B$51*'Б1.1.1'!$B$50*'Б1.1.1'!$B$41 -> 0 | N35: ='Б1.1.1'!$B$32*'Б1.1.1'!$B$51*'Б1.1.1'!$B$50*'Б1.1.1'!$B$41 -> 0 | O35: ='Б1.1.1'!$B$32*'Б1.1.1'!$B$51*'Б1.1.1'!$B$50*'Б1.1.1'!$B$41 -> 0 | P35: ='Б1.1.1'!$B$32*'Б1.1.1'!$B$51*'Б1.1.1'!$B$50*'Б1.1.1'!$B$41 -> 0 | Q35: =P35*12 -> 0 | R35: =P35*12 -> 0
A36: 1.5.3. Расходы на удаленный доступ для системы, руб. | B36: РКом 3 | C36: =D36+Q36+R36+S36+T36 -> 0 | D36: =SUM(E36:P36) -> 0 | H36: ='Б1.1.1'!$B$32*'Б1.1.1'!$B$51*'Б1.1.1'!$B$50*'Б1.1.1'!$B$41 -> 0 | I36: ='Б1.1.1'!$B$32*'Б1.1.1'!$B$51*'Б1.1.1'!$B$50*'Б1.1.1'!$B$41 -> 0 | J36: ='Б1.1.1'!$B$32*'Б1.1.1'!$B$51*'Б1.1.1'!$B$50*'Б1.1.1'!$B$41 -> 0 | K36: ='Б1.1.1'!$B$32*'Б1.1.1'!$B$51*'Б1.1.1'!$B$50*'Б1.1.1'!$B$41 -> 0 | L36: ='Б1.1.1'!$B$32*'Б1.1.1'!$B$51*'Б1.1.1'!$B$50*'Б1.1.1'!$B$41 -> 0 | M36: ='Б1.1.1'!$B$32*'Б1.1.1'!$B$51*'Б1.1.1'!$B$50*'Б1.1.1'!$B$41 -> 0 | N36: ='Б1.1.1'!$B$32*'Б1.1.1'!$B$51*'Б1.1.1'!$B$50*'Б1.1.1'!$B$41 -> 0 | O36: ='Б1.1.1'!$B$32*'Б1.1.1'!$B$51*'Б1.1.1'!$B$50*'Б1.1.1'!$B$41 -> 0 | P36: ='Б1.1.1'!$B$32*'Б1.1.1'!$B$51*'Б1.1.1'!$B$50*'Б1.1.1'!$B$41 -> 0 | Q36: =P36*12 -> 0 | R36: =P36*12 -> 0 | U36: второй и последующие годы =месяц*12
A37: 1.5.4. Стоимость поддержки и развития корпоративных сетей передачи данных для системы, руб. | B37: РКом 4 | C37: =D37+Q37+R37+S37+T37 -> 0 | D37: =SUM(E37:P37) -> 0 | H37: ='Б1.1.1'!$B$32*'Б1.1.1'!$B$51*'Б1.1.1'!$B$50*'Б1.1.1'!$B$41 -> 0 | I37: ='Б1.1.1'!$B$32*'Б1.1.1'!$B$51*'Б1.1.1'!$B$50*'Б1.1.1'!$B$41 -> 0 | J37: ='Б1.1.1'!$B$32*'Б1.1.1'!$B$51*'Б1.1.1'!$B$50*'Б1.1.1'!$B$41 -> 0 | K37: ='Б1.1.1'!$B$32*'Б1.1.1'!$B$51*'Б1.1.1'!$B$50*'Б1.1.1'!$B$41 -> 0 | L37: ='Б1.1.1'!$B$32*'Б1.1.1'!$B$51*'Б1.1.1'!$B$50*'Б1.1.1'!$B$41 -> 0 | M37: ='Б1.1.1'!$B$32*'Б1.1.1'!$B$51*'Б1.1.1'!$B$50*'Б1.1.1'!$B$41 -> 0 | N37: ='Б1.1.1'!$B$32*'Б1.1.1'!$B$51*'Б1.1.1'!$B$50*'Б1.1.1'!$B$41 -> 0 | O37: ='Б1.1.1'!$B$32*'Б1.1.1'!$B$51*'Б1.1.1'!$B$50*'Б1.1.1'!$B$41 -> 0 | P37: ='Б1.1.1'!$B$32*'Б1.1.1'!$B$51*'Б1.1.1'!$B$50*'Б1.1.1'!$B$41 -> 0 | Q37: =P37*12 -> 0 | R37: =P37*12 -> 0

Sheet В1.2.2
T1: Таблица В1.2.2
A3: Расчет расходов (условно-косвенных), связанных с эксплуатацией ИТ-проекта
A5: Статья затрат | B5: Обозна- чение | C5: Всего | D5: в т.ч. по периодам эксплуатации системы
D6: 1 год, всего | E6: в т.ч. по периодам (месяцам) 1-го года жизни решения | Q6: 2 | R6: 3 | S6: 4 | T6: 5
E7: 1 месяц (разработка) | F7: 2 месяц (разработка) | G7: 3 месяц (разработка) | H7: 4 месяц | I7: 5 месяц | J7: 6 месяц | K7: 7 месяц | L7: 8 месяц | M7: 9 месяц | N7: 10 месяц | O7: 11 месяц | P7: 12 месяц
A8: 2. Условно-косвенные расходы по подсистеме (системе), руб. | B8: РКос | C8: =D8+Q8+R8+S8+T8 -> 7787837.6 | D8: =D9+D17+D23+D29+D37 -> 2127604.3 | E8: =E9+E17+E23+E29+E37 -> 0 | F8: =F9+F17+F23+F29+F37 -> 0 | G8: =G9+G17+G23+G29+G37 -> 0 | H8: =H9+H17+H23+H29+H37 -> 235093.06 | I8: =I9+I17+I23+I29+I37 -> 235093.06 | J8: =J9+J17+J23+J29+J37 -> 235093.06 | K8: =K9+K17+K23+K29+K37 -> 235093.06 | ... T8: =T9+T17+T23+T29+T37 -> 0
A9: 2.1. Косвенные расходы на общесистемное оборудование, руб. | B9: РКОб | C9: =D9+Q9+R9+S9+T9 -> 7178176.1 | D9: =SUM(D10:D15) -> 1959320.8 | E9: =SUM(E10:E15)*E16 -> 0 | F9: =SUM(F10:F15)*F16 -> 0 | G9: =SUM(G10:G15)*G16 -> 0 | H9: =SUM(H10:H15)*H16 -> 216702.31 | I9: =SUM(I10:I15)*I16 -> 216702.31 | J9: =SUM(J10:J15)*J16 -> 216702.31 | K9: =SUM(K10:K15)*K16 -> 216702.31 | L9: =SUM(L10:L15)*L16 -> 216702.31 | ... T9: =SUM(T10:T15)*T16 -> 0
A10: 2.1.1. Расходы на закупку общесистемного оборудования в год, руб. | B10: РКОб 1 | C10: =D10+Q10*$Q$16+R10*$R$16+S10*$S$16+T10*$T$16 -> 0 | D10: =SUM(E10:P10)*$D$16 -> 0
A11: 2.1.2. Сумма амортизации капитальных вложений в общесистемное оборудование, руб. | B11: РКОб 2 | C11: =D11+Q11*$Q$16+R11*$R$16+S11*$S$16+T11*$T$16 -> 7150000 | D11: =SUM(E11:P11)*$D$16 -> 1950000 | H11: ='Б1.1.1'!$B$37/'Б1.1.1'!$B$5 -> 722222.22 | I11: ='Б1.1.1'!$B$37/'Б1.1.1'!$B$5 -> 722222.22 | J11: ='Б1.1.1'!$B$37/'Б1.1.1'!$B$5 -> 722222.22 | K11: ='Б1.1.1'!$B$37/'Б1.1.1'!$B$5 -> 722222.22 | L11: ='Б1.1.1'!$B$37/'Б1.1.1'!$B$5 -> 722222.22 | M11: ='Б1.1.1'!$B$37/'Б1.1.1'!$B$5 -> 722222.22 | N11: ='Б1.1.1'!$B$37/'Б1.1.1'!$B$5 -> 722222.22 | O11: ='Б1.1.1'!$B$37/'Б1.1.1'!$B$5 -> 722222.22 | P11: ='Б1.1.1'!$B$37/'Б1.1.1'!$B$5 -> 722222.22 | Q11: =P11*12 -> 8666666.7 | R11: =P11*12 -> 8666666.7 | S11: 0 | T11: 0 | U11: второй и последующие годы =месяц*12
A12: 2.1.3. Расходы на общесистемные комплектующие за год, руб. | B12: РКОб 3 | C12: =D12+Q12*$Q$16+R12*$R$16+S12*$S$16+T12*$T$16 -> 0 | D12: =SUM(E12:P12)*$D$16 -> 0 | Q12: =P12*12 -> 0 | R12: =P12*12 -> 0
A13: 2.1.4. Расходы на эксплуатацию общесистемного оборудования, руб. | B13: РКОб 4 | C13: =D13+Q13*$Q$16+R13*$R$16+S13*$S$16+T13*$T$16 -> 1176.12 | D13: =SUM(E13:P13)*$D$16 -> 320.76 | H13: ='Б1.1.1'!$B$13+'Б1.1.1'!$B$14*'Б1.1.1'!$B$15*'Б1.1.1'!$B$12*0.9 -> 118.8 | I13: ='Б1.1.1'!$B$13+'Б1.1.1'!$B$14*'Б1.1.1'!$B$15*'Б1.1.1'!$B$12*0.9 -> 118.8 | J13: ='Б1.1.1'!$B$13+'Б1.1.1'!$B$14*'Б1.1.1'!$B$15*'Б1.1.1'!$B$12*0.9 -> 118.8 | K13: ='Б1.1.1'!$B$13+'Б1.1.1'!$B$14*'Б1.1.1'!$B$15*'Б1.1.1'!$B$12*0.9 -> 118.8 | L13: ='Б1.1.1'!$B$13+'Б1.1.1'!$B$14*'Б1.1.1'!$B$15*'Б1.1.1'!$B$12*0.9 -> 118.8 | M13: ='Б1.1.1'!$B$13+'Б1.1.1'!$B$14*'Б1.1.1'!$B$15*'Б1.1.1'!$B$12*0.9 -> 118.8 | N13: ='Б1.1.1'!$B$13+'Б1.1.1'!$B$14*'Б1.1.1'!$B$15*'Б1.1.1'!$B$12*0.9 -> 118.8 | O13: ='Б1.1.1'!$B$13+'Б1.1.1'!$B$14*'Б1.1.1'!$B$15*'Б1.1.1'!$B$12*0.9 -> 118.8 | P13: ='Б1.1.1'!$B$13+'Б1.1.1'!$B$14*'Б1.1.1'!$B$15*'Б1.1.1'!$B$12*0.9 -> 118.8 | Q13: =P13*12 -> 1425.6 | R13: =P13*12 -> 1425.6
A14: 2.1.5. Ежегодная стоимость обслуживания общесистемного оборудования по договору, руб. | B14: РКОб 5 | C14: =D14+Q14*$Q$16+R14*$R$16+S14*$S$16+T14*$T$16 -> 27000 | D14: =SUM(E14:P14)*$D$16 -> 9000 | P14: ='Б1.1.1'!B38 -> 30000 | Q14: =P14 -> 30000 | R14: =P14 -> 30000
A15: 2.1.6. Ежегодная стоимость аренды общесистемного оборудования, руб. | B15: РКОб 6 | C15: =D15+Q15*$Q$16+R15*$R$16+S15*$S$16+T15*$T$16 -> 0 | D15: =SUM(E15:P15)*$D$16 -> 0
A16: 2.1.7. Коэффициент участия общесистемного оборудования в системе | B16: РУОб | C16: =(D16+Q16+R16+S16+T16)/5 -> 0.3 | D16: =SUM(E16:P16)/12 -> 0.3 | E16: 0.3 | F16: 0.3 | G16: 0.3 | H16: 0.3 | I16: 0.3 | J16: 0.3 | K16: 0.3 | L16: 0.3 | M16: 0.3 | N16: 0.3 | O16: 0.3 | P16: 0.3 | Q16: 0.3 | R16: 0.3 | S16: 0.3 | T16: 0.3
A17: 2.2. Косвенные расходы на общесистемное программное обеспечение (ПО), РУб- | B17: РКПО | C17: =D17+Q17+R17+S17+T17 -> 0 | D17: =SUM(D18:D21) -> 0 | E17: =SUM(E18:E21)*E22 -> 0 | F17: =SUM(F18:F21)*F22 -> 0 | G17: =SUM(G18:G21)*G22 -> 0 | H17: =SUM(H18:H21)*H22 -> 0 | I17: =SUM(I18:I21)*I22 -> 0 | J17: =SUM(J18:J21)*J22 -> 0 | K17: =SUM(K18:K21)*K22 -> 0 | L17: =SUM(L18:L21)*L22 -> 0 | ... T17: =SUM(T18:T21)*T22 -> 0
A18: 2.2.1. Расходы на закупку общесистемного ПО за год, руб. | B18: РКПО 1 | C18: =D18+Q18*$Q$22+R18*$R$22+S18*$S$22+T18*$T$22 -> 0 | D18: =SUM(E18:P18)*$D$22 -> 0 | H18: ='Б1.1.1'!$B$39/'Б1.1.1'!$B$18 -> 0 | I18: ='Б1.1.1'!$B$39/'Б1.1.1'!$B$18 -> 0 | J18: ='Б1.1.1'!$B$39/'Б1.1.1'!$B$18 -> 0 | K18: 0 | L18: 0 | M18: 0 | N18: 0 | O18: 0 | P18: 0 | Q18: 0 | R18: 0 | S18: 0 | T18: 0
A19: 2.2.2. Сумма ежегодного списания затрат на общесистемное ПО, руб. | B19: РКПО 2 | C19: =D19+Q19*$Q$22+R19*$R$22+S19*$S$22+T19*$T$22 -> 0 | D19: =SUM(E19:P19)*$D$22 -> 0 | H19: ='Б1.1.1'!$B$39/'Б1.1.1'!$B$18 -> 0 | I19: ='Б1.1.1'!$B$39/'Б1.1.1'!$B$18 -> 0 | J19: ='Б1.1.1'!$B$39/'Б1.1.1'!$B$18 -> 0 | K19: ='Б1.1.1'!$B$39/'Б1.1.1'!$B$18 -> 0 | L19: ='Б1.1.1'!$B$39/'Б1.1.1'!$B$18 -> 0 | M19: ='Б1.1.1'!$B$39/'Б1.1.1'!$B$18 -> 0 | N19: ='Б1.1.1'!$B$39/'Б1.1.1'!$B$18 -> 0 | O19: ='Б1.1.1'!$B$39/'Б1.1.1'!$B$18 -> 0 | P19: ='Б1.1.1'!$B$39/'Б1.1.1'!$B$18 -> 0 | Q19: =$P$19*12 -> 0 | R19: =$P$19*12 -> 0 | S19: 0 | T19: 0 | U19: второй и последующие годы =месяц*12
A20: 2.2.3. Ежегодные затраты на аренду общесистемного ПО, руб. | B20: РКПО 3 | C20: =D20+Q20*$Q$22+R20*$R$22+S20*$S$22+T20*$T$22 -> 0 | D20: =SUM(E20:P20)*$D$22 -> 0 | H20: ='Б1.1.1'!$B$39/'Б1.1.1'!$B$18 -> 0 | I20: ='Б1.1.1'!$B$39/'Б1.1.1'!$B$18 -> 0 | J20: ='Б1.1.1'!$B$39/'Б1.1.1'!$B$18 -> 0 | K20: ='Б1.1.1'!$B$39/'Б1.1.1'!$B$18 -> 0 | L20: ='Б1.1.1'!$B$39/'Б1.1.1'!$B$18 -> 0 | M20: ='Б1.1.1'!$B$39/'Б1.1.1'!$B$18 -> 0 | N20: ='Б1.1.1'!$B$39/'Б1.1.1'!$B$18 -> 0 | O20: ='Б1.1.1'!$B$39/'Б1.1.1'!$B$18 -> 0 | P20: ='Б1.1.1'!$B$39/'Б1.1.1'!$B$18 -> 0 | Q20: =$P$19*12 -> 0 | R20: =$P$19*12 -> 0 | S20: 0 | T20: 0
A21: 2.2.4. Стоимость актуализации, поддержки и сопровождения общесистемного ПО за год, руб. | B21: РКПО 4 | C21: =D21+Q21*$Q$22+R21*$R$22+S21*$S$22+T21*$T$22 -> 0 | D21: =SUM(E21:P21)*$D$22 -> 0 | H21: ='Б1.1.1'!$B$39/'Б1.1.1'!$B$18 -> 0 | I21: ='Б1.1.1'!$B$39/'Б1.1.1'!$B$18 -> 0 | J21: ='Б1.1.1'!$B$39/'Б1.1.1'!$B$18 -> 0 | K21: ='Б1.1.1'!$B$39/'Б1.1.1'!$B$18 -> 0 | L21: ='Б1.1.1'!$B$39/'Б1.1.1'!$B$18 -> 0 | M21: ='Б1.1.1'!$B$39/'Б1.1.1'!$B$18 -> 0 | N21: ='Б1.1.1'!$B$39/'Б1.1.1'!$B$18 -> 0 | O21: ='Б1.1.1'!$B$39/'Б1.1.1'!$B$18 -> 0 | P21: ='Б1.1.1'!$B$39/'Б1.1.1'!$B$18 -> 0 | Q21: =$P$19*12 -> 0 | R21: =$P$19*12 -> 0 | S21: 0 | T21: 0
A22: 2.2.5. Коэффициент участия общесистемного ПО в подсистеме | B22: РУПО | C22: =(D22+Q22+R22+S22+T22)/5 -> 0.2 | D22: =SUM(E22:P22)/12 -> 0.2 | E22: 0.2 | F22: 0.2 | G22: 0.2 | H22: 0.2 | I22: 0.2 | J22: 0.2 | K22: 0.2 | L22: 0.2 | M22: 0.2 | N22: 0.2 | O22: 0.2 | P22: 0.2 | Q22: 0.2 | R22: 0.2 | S22: 0.2 | T22: 0.2
A23: 2.3. Косвенные административные расходы, руб. | B23: РКАдм | C23: =D23+Q23+R23+S23+T23 -> 515592 | D23: =SUM(D24:D27) -> 140616 | E23: =SUM(E24:E27)*E28 -> 0 | F23: =SUM(F24:F27)*F28 -> 0 | G23: =SUM(G24:G27)*G28 -> 0 | H23: =SUM(H24:H27)*H28 -> 15624 | I23: =SUM(I24:I27)*I28 -> 15624 | J23: =SUM(J24:J27)*J28 -> 15624 | K23: =SUM(K24:K27)*K28 -> 15624 | L23: =SUM(L24:L27)*L28 -> 15624 | ... T23: =SUM(T24:T27)*T28 -> 0
A24: 2.3.1. Расходы на оплату труда лиц, работающих со всей системой (общесистемный персонал), за год, руб. | B24: РКАдм 1 | C24: =D24+Q24*$Q$28+R24*$R$28+S24*$S$28+T24*$T$28 -> 515592 | D24: =SUM(E24:P24)*$D$28 -> 140616 | H24: ='Б1.1.1'!B34*'Б1.1.1'!$B$53*'Б1.1.1'!$B$41 -> 156240 | I24: ='Б1.1.1'!B34*'Б1.1.1'!$B$53*'Б1.1.1'!$B$41 -> 156240 | J24: ='Б1.1.1'!B34*'Б1.1.1'!$B$53*'Б1.1.1'!$B$41 -> 156240 | K24: ='Б1.1.1'!B34*'Б1.1.1'!$B$53*'Б1.1.1'!$B$41 -> 156240 | L24: ='Б1.1.1'!B34*'Б1.1.1'!$B$53*'Б1.1.1'!$B$41 -> 156240 | M24: ='Б1.1.1'!B34*'Б1.1.1'!$B$53*'Б1.1.1'!$B$41 -> 156240 | N24: ='Б1.1.1'!B34*'Б1.1.1'!$B$53*'Б1.1.1'!$B$41 -> 156240 | O24: ='Б1.1.1'!B34*'Б1.1.1'!$B$53*'Б1.1.1'!$B$41 -> 156240 | P24: ='Б1.1.1'!B34*'Б1.1.1'!$B$53*'Б1.1.1'!$B$41 -> 156240 | Q24: =O24*12 -> 1874880 | R24: =P24*12 -> 1874880 | W24: в год *12 мес
A25: 2.3.2. Расходы на консультационные услуги третьих фирм и аналогичные платежи за год, относящиеся ко всей системе организации, руб. | B25: РКАдм 2 | C25: =D25+Q25*$Q$28+R25*$R$28+S25*$S$28+T25*$T$28 -> 0 | D25: =SUM(E25:P25)*$D$28 -> 0
A26: 2.3.3. Ежегодные расходы на решение задач общесистемного характера, порученных другим организациям в порядке аутсорсинга, руб. | B26: РКАдм 3 | C26: =D26+Q26*$Q$28+R26*$R$28+S26*$S$28+T26*$T$28 -> 0 | D26: =SUM(E26:P26)*$D$28 -> 0
A27: 2.3.4. Ежегодные затраты на обучение персонала вопросам информационных технологий и систем информационного менеджмента в целом, руб. | B27: РКАдм 4 | C27: =D27+Q27*$Q$28+R27*$R$28+S27*$S$28+T27*$T$28 -> 0 | D27: =SUM(E27:P27)*$D$28 -> 0
A28: 2.3.5. Коэффициент участия общесистемного персонала в подсистеме | B28: РУАдм | C28: =(D28+Q28+R28+S28+T28)/5 -> 0.1 | D28: =SUM(E28:P28)/12 -> 0.1 | E28: 0.1 | F28: 0.1 | G28: 0.1 | H28: 0.1 | I28: 0.1 | J28: 0.1 | K28: 0.1 | L28: 0.1 | M28: 0.1 | N28: 0.1 | O28: 0.1 | P28: 0.1 | Q28: 0.1 | R28: 0.1 | S28: 0.1 | T28: 0.1
A29: 2.4. Косвенные расходы на оплату труда, связанные с сопровождением и развитием системы, руб. | B29: РКФОТ | C29: =C30+C33 -> 691687.5 | D29: =D30+D33 -> 27667.5 | E29: =E30*E36+E33*E36 -> 0 | F29: =F30*F36+F33*F36 -> 0 | G29: =G30*G36+G33*G36 -> 0 | H29: =H30*H36+H33*H36 -> 2766.75 | I29: =I30*I36+I33*I36 -> 2766.75 | J29: =J30*J36+J33*J36 -> 2766.75 | K29: =K30*K36+K33*K36 -> 2766.75 | L29: =L30*L36+L33*L36 -> 2766.75 | ... T29: =T30*T36+T33*T36 -> 0
A30: 2.4.1. Расходы на оплату труда сотрудников по сопровождению и развитию общесистемных ресурсов информационного менеджмента в течение года, руб., Всего в т.ч.: | B30: РКФОТ 1 | C30: =C31+C32 -> 691687.5 | D30: =SUM(D31:D32) -> 27667.5 | E30: =SUM(E31:E32) -> 0 | F30: =SUM(F31:F32) -> 0 | G30: =SUM(G31:G32) -> 0 | H30: =SUM(H31:H32) -> 27667.5 | I30: =SUM(I31:I32) -> 27667.5 | J30: =SUM(J31:J32) -> 27667.5 | K30: =SUM(K31:K32) -> 27667.5 | ... P30: =SUM(P31:P32) -> 55335 | Q30: =SUM(Q31+Q32) -> 332010 | R30: =SUM(R31+R32) -> 332010 | S30: =SUM(S31+S32) -> 0 | T30: =SUM(T31+T32) -> 0
A31: сопровождение | B31: РКФОТ 1_1 | C31: =D31+Q31+R31+S31+T31 -> 688920.75 | D31: =SUM(E31:P31)*$D$36 -> 24900.75 | H31: ='Б1.1.1'!$B$26*'Б1.1.1'!$B$27*'Б1.1.1'!$B$41 -> 27667.5 | I31: ='Б1.1.1'!$B$26*'Б1.1.1'!$B$27*'Б1.1.1'!$B$41 -> 27667.5 | J31: ='Б1.1.1'!$B$26*'Б1.1.1'!$B$27*'Б1.1.1'!$B$41 -> 27667.5 | K31: ='Б1.1.1'!$B$26*'Б1.1.1'!$B$27*'Б1.1.1'!$B$41 -> 27667.5 | L31: ='Б1.1.1'!$B$26*'Б1.1.1'!$B$27*'Б1.1.1'!$B$41 -> 27667.5 | M31: ='Б1.1.1'!$B$26*'Б1.1.1'!$B$27*'Б1.1.1'!$B$41 -> 27667.5 | N31: ='Б1.1.1'!$B$26*'Б1.1.1'!$B$27*'Б1.1.1'!$B$41 -> 27667.5 | O31: ='Б1.1.1'!$B$26*'Б1.1.1'!$B$27*'Б1.1.1'!$B$41 -> 27667.5 | P31: ='Б1.1.1'!$B$26*'Б1.1.1'!$B$27*'Б1.1.1'!$B$41 -> 27667.5 | Q31: =P31*12 -> 332010 | R31: =P31*12 -> 332010
A32: развитие | B32: РКФОТ 1_2 | C32: =D32+Q32+R32+S32+T32 -> 2766.75 | D32: =SUM(E32:P32)*$D$36 -> 2766.75 | P32: ='Б1.1.1'!$B$26*'Б1.1.1'!$B$27*'Б1.1.1'!$B$41 -> 27667.5
A33: 2.4.2. Расходы на оплату услуг сторонних консультантов и сервисных организаций в части развития и сопровождения общесистемных ресурсов информационного менеджмента в течение года, Всего в т.ч. | B33: РКФОТ 2 | C33: =C34+C35 -> 0 | D33: =SUM(D34:D35) -> 0 | E33: =SUM(E34:E35)*E$36 -> 0 | F33: =SUM(F34:F35)*F$36 -> 0 | G33: =SUM(G34:G35)*G$36 -> 0 | H33: =SUM(H34:H35)*H$36 -> 0 | I33: =SUM(I34:I35)*I$36 -> 0 | J33: =SUM(J34:J35)*J$36 -> 0 | K33: =SUM(K34:K35)*K$36 -> 0 | L33: =SUM(L34:L35)*L$36 -> 0 | ... P33: =SUM(P34:P35)*P$36 -> 0 | Q33: =SUM(Q34+Q35)*Q$36 -> 0 | R33: =SUM(R34+R35)*R$36 -> 0 | S33: =SUM(S34+S35)*S$36 -> 0 | T33: =SUM(T34+T35)*T$36 -> 0
A34: сопровождение | B34: РКФОТ 2_1 | C34: =D34+Q34*$Q$36+R34*$R$36+S34*$S$36+T34*$T$36 -> 0 | D34: =SUM(E34:P34)*$D$36 -> 0
A35: развитие | B35: РКФОТ 2_2 | C35: =D35+Q35*$Q$36+R35*$R$36+S35*$S$36+T35*$T$36 -> 0 | D35: =SUM(E35:P35)*$D$36 -> 0
